<?xml version="1.0" encoding="UTF-8"?>
<robot name="ur20">
  <link name="world"></link>
  <link name="base_link"></link>
  <link name="base_link_inertia">
    <visual>
      <origin rpy="0.0 0.0 3.141592653589793" xyz="0.0 0.0 0.0"/>
      <geometry>
        <mesh filename="package://ur_description/meshes/ur20/visual/base.dae"/>
      </geometry>
    </visual>
    <collision>
      <origin rpy="0.0 0.0 3.141592653589793" xyz="0.0 0.0 0.0"/>
      <geometry>
        <mesh filename="package://ur_description/meshes/ur20/collision/base.stl"/>
      </geometry>
    </collision>
    <inertial>
      <mass value="4.0"/>
      <origin rpy="0 0 0" xyz="0 0 0"/>
      <inertia ixx="0.0061063308908" ixy="0.0" ixz="0.0" iyy="0.0061063308908" iyz="0.0" izz="0.01125"/>
    </inertial>
  </link>
  <link name="shoulder_link">
    <visual>
      <origin rpy="0.0 0.0 3.141592653589793" xyz="0.0 0.0 0.0"/>
      <geometry>
        <mesh filename="package://ur_description/meshes/ur20/visual/shoulder.dae"/>
      </geometry>
    </visual>
    <collision>
      <origin rpy="0.0 0.0 3.141592653589793" xyz="0.0 0.0 0.0"/>
      <geometry>
        <mesh filename="package://ur_description/meshes/ur20/collision/shoulder.stl"/>
      </geometry>
    </collision>
    <inertial>
      <mass value="16.343"/>
      <origin rpy="1.570796326794897 0 0" xyz="0.0 -0.0062 -0.061"/>
      <inertia ixx="0.08866" ixy="-0.00011" ixz="-0.00011" iyy="0.07632" iyz="0.0072" izz="0.08418"/>
    </inertial>
  </link>
  <link name="upper_arm_link">
    <visual>
      <origin rpy="1.5707963267948966 0.0 -1.5707963267948966" xyz="0.0 0.0 0.26"/>
      <geometry>
        <mesh filename="package://ur_description/meshes/ur20/visual/upperarm.dae"/>
      </geometry>
    </visual>
    <collision>
      <origin rpy="1.5707963267948966 0.0 -1.5707963267948966" xyz="0.0 0.0 0.26"/>
      <geometry>
        <mesh filename="package://ur_description/meshes/ur20/collision/upperarm.stl"/>
      </geometry>
    </collision>
    <inertial>
      <mass value="29.632"/>
      <origin rpy="0 0 0" xyz="-0.3394 0.0 0.2098"/>
      <inertia ixx="0.1467" ixy="0.00019" ixz="-0.05163" iyy="4.6659" iyz="4e-05" izz="4.6348"/>
    </inertial>
  </link>
  <link name="forearm_link">
    <visual>
      <origin rpy="1.5707963267948966 0.0 -1.5707963267948966" xyz="0.0 0.0 0.043"/>
      <geometry>
        <mesh filename="package://ur_description/meshes/ur20/visual/forearm.dae"/>
      </geometry>
    </visual>
    <collision>
      <origin rpy="1.5707963267948966 0.0 -1.5707963267948966" xyz="0.0 0.0 0.043"/>
      <geometry>
        <mesh filename="package://ur_description/meshes/ur20/collision/forearm.stl"/>
      </geometry>
    </collision>
    <inertial>
      <mass value="7.879"/>
      <origin rpy="0 0 0" xyz="-0.4053 0.0 0.0604"/>
      <inertia ixx="0.02612" ixy="-5e-05" ixz="-0.02898" iyy="0.75763" iyz="-1e-05" izz="0.75327"/>
    </inertial>
  </link>
  <link name="wrist_1_link">
    <visual>
      <origin rpy="1.5707963267948966 0.0 0.0" xyz="0.0 0.0 -0.0775"/>
      <geometry>
        <mesh filename="package://ur_description/meshes/ur20/visual/wrist1.dae"/>
      </geometry>
    </visual>
    <collision>
      <origin rpy="1.5707963267948966 0.0 0.0" xyz="0.0 0.0 -0.0775"/>
      <geometry>
        <mesh filename="package://ur_description/meshes/ur20/collision/wrist1.stl"/>
      </geometry>
    </collision>
    <inertial>
      <mass value="3.054"/>
      <origin rpy="1.570796326794897 0 0" xyz="0.0 -0.0393 -0.0026"/>
      <inertia ixx="0.00555" ixy="-1e-05" ixz="-2e-05" iyy="0.00537" iyz="0.00036" izz="0.00402"/>
    </inertial>
  </link>
  <link name="wrist_2_link">
    <visual>
      <origin rpy="0.0 0.0 0.0" xyz="0.0 0.0 -0.0749"/>
      <geometry>
        <mesh filename="package://ur_description/meshes/ur20/visual/wrist2.dae"/>
      </geometry>
    </visual>
    <collision>
      <origin rpy="0.0 0.0 0.0" xyz="0.0 0.0 -0.0749"/>
      <geometry>
        <mesh filename="package://ur_description/meshes/ur20/collision/wrist2.stl"/>
      </geometry>
    </collision>
    <inertial>
      <mass value="3.126"/>
      <origin rpy="-1.570796326794897 0 0" xyz="0.0 0.0379 -0.0024"/>
      <inertia ixx="0.00586" ixy="-1e-05" ixz="-2e-05" iyy="0.00578" iyz="-0.00037" izz="0.00427"/>
    </inertial>
  </link>
  <link name="wrist_3_link">
    <visual>
      <origin rpy="1.5707963267948966 0.0 0.0" xyz="0.0 0.0 -0.07"/>
      <geometry>
        <mesh filename="package://ur_description/meshes/ur20/visual/wrist3.dae"/>
      </geometry>
    </visual>
    <collision>
      <origin rpy="1.5707963267948966 0.0 0.0" xyz="0.0 0.0 -0.07"/>
      <geometry>
        <mesh filename="package://ur_description/meshes/ur20/collision/wrist3.stl"/>
      </geometry>
    </collision>
    <inertial>
      <mass value="0.926"/>
      <origin rpy="0 0 0" xyz="0.0 0.0 -0.0293"/>
      <inertia ixx="0.00092" ixy="0.0" ixz="0.0" iyy="0.00091" iyz="0.0" izz="0.00117"/>
    </inertial>
  </link>
  <link name="flange"></link>
  <joint name="base_joint" type="fixed">
    <parent link="world"></parent>
    <child link="base_link"></child>
    <origin xyz="0 0 0" rpy="0 0 0"></origin>
    <origin rpy="0 0 0" xyz="0 0 0"/>
    <parent link="world"/>
    <child link="base_link"/>
  
  </joint>
  <joint name="base_link-base_link_inertia" type="fixed">
    <parent link="base_link"></parent>
    <child link="base_link_inertia"></child>
    <origin xyz="0 0 0" rpy="0 0 3.141592653589793"></origin>
    <parent link="base_link"/>
    <child link="base_link_inertia"/>
    <!-- 'base_link' is REP-103 aligned (so X+ forward), while the internal
           frames of the robot/controller have X+ pointing backwards.
           Use the joint between 'base_link' and 'base_link_inertia' (a dummy
           link/frame) to introduce the necessary rotation over Z (of pi rad).
      -->
    <origin rpy="0 0 3.141592653589793" xyz="0 0 0"/>
  
  </joint>
  <joint name="shoulder_pan_joint" type="revolute">
    <parent link="base_link_inertia"></parent>
    <child link="shoulder_link"></child>
    <origin xyz="0 0 0.2363" rpy="0 0 0"></origin>
    <axis xyz="0 0 1"></axis>
    <limit lower="-6.283185307179586" upper="6.283185307179586" effort="738.0" velocity="2.0943951023931953"></limit>
    <parent link="base_link_inertia"/>
    <child link="shoulder_link"/>
    <origin rpy="0 0 0" xyz="0 0 0.2363"/>
    <axis xyz="0 0 1"/>
    <limit effort="738.0" lower="-6.283185307179586" upper="6.283185307179586" velocity="2.0943951023931953"/>
    <dynamics damping="0" friction="0"/>
  
  </joint>
  <joint name="shoulder_lift_joint" type="revolute">
    <parent link="shoulder_link"></parent>
    <child link="upper_arm_link"></child>
    <origin xyz="0 0 0" rpy="1.570796327 0 0"></origin>
    <axis xyz="0 0 1"></axis>
    <limit lower="-6.283185307179586" upper="6.283185307179586" effort="738.0" velocity="2.0943951023931953"></limit>
    <parent link="shoulder_link"/>
    <child link="upper_arm_link"/>
    <origin rpy="1.570796327 0 0" xyz="0 0 0"/>
    <axis xyz="0 0 1"/>
    <limit effort="738.0" lower="-6.283185307179586" upper="6.283185307179586" velocity="2.0943951023931953"/>
    <dynamics damping="0" friction="0"/>
  
  </joint>
  <joint name="elbow_joint" type="revolute">
    <parent link="upper_arm_link"></parent>
    <child link="forearm_link"></child>
    <origin xyz="-0.862 0 0" rpy="0 0 0"></origin>
    <axis xyz="0 0 1"></axis>
    <limit lower="-3.141592653589793" upper="3.141592653589793" effort="433.0" velocity="2.6179938779914944"></limit>
    <parent link="upper_arm_link"/>
    <child link="forearm_link"/>
    <origin rpy="0 0 0" xyz="-0.862 0 0"/>
    <axis xyz="0 0 1"/>
    <limit effort="433.0" lower="-3.141592653589793" upper="3.141592653589793" velocity="2.6179938779914944"/>
    <dynamics damping="0" friction="0"/>
  
  </joint>
  <joint name="wrist_1_joint" type="revolute">
    <parent link="forearm_link"></parent>
    <child link="wrist_1_link"></child>
    <origin xyz="-0.7287 0 0.201" rpy="0 0 0"></origin>
    <axis xyz="0 0 1"></axis>
    <limit lower="-6.283185307179586" upper="6.283185307179586" effort="107.0" velocity="3.6651914291880923"></limit>
    <parent link="forearm_link"/>
    <child link="wrist_1_link"/>
    <origin rpy="0 0 0" xyz="-0.7287 0 0.201"/>
    <axis xyz="0 0 1"/>
    <limit effort="107.0" lower="-6.283185307179586" upper="6.283185307179586" velocity="3.6651914291880923"/>
    <dynamics damping="0" friction="0"/>
  
  </joint>
  <joint name="wrist_2_joint" type="revolute">
    <parent link="wrist_1_link"></parent>
    <child link="wrist_2_link"></child>
    <origin xyz="0 -0.1593 -3.267297616249225e-11" rpy="1.570796327 0 0"></origin>
    <axis xyz="0 0 1"></axis>
    <limit lower="-6.283185307179586" upper="6.283185307179586" effort="107.0" velocity="3.6651914291880923"></limit>
    <parent link="wrist_1_link"/>
    <child link="wrist_2_link"/>
    <origin rpy="1.570796327 0 0" xyz="0 -0.1593 -3.267297616249225e-11"/>
    <axis xyz="0 0 1"/>
    <limit effort="107.0" lower="-6.283185307179586" upper="6.283185307179586" velocity="3.6651914291880923"/>
    <dynamics damping="0" friction="0"/>
  
  </joint>
  <joint name="wrist_3_joint" type="revolute">
    <parent link="wrist_2_link"></parent>
    <child link="wrist_3_link"></child>
    <origin xyz="0 0.1543 -3.1647459019915597e-11" rpy="1.570796326589793 3.141592653589793 3.141592653589793"></origin>
    <axis xyz="0 0 1"></axis>
    <limit lower="-6.283185307179586" upper="6.283185307179586" effort="107.0" velocity="3.6651914291880923"></limit>
    <parent link="wrist_2_link"/>
    <child link="wrist_3_link"/>
    <origin rpy="1.570796326589793 3.141592653589793 3.141592653589793" xyz="0 0.1543 -3.1647459019915597e-11"/>
    <axis xyz="0 0 1"/>
    <limit effort="107.0" lower="-6.283185307179586" upper="6.283185307179586" velocity="3.6651914291880923"/>
    <dynamics damping="0" friction="0"/>
  
  </joint>
  <joint name="wrist_3-flange" type="fixed">
    <parent link="wrist_3_link"></parent>
    <child link="flange"></child>
    <origin xyz="0 0 0" rpy="0 -1.5707963267948966 -1.5707963267948966"></origin>
    <parent link="wrist_3_link"/>
    <child link="flange"/>
    <origin rpy="0 -1.5707963267948966 -1.5707963267948966" xyz="0 0 0"/>
  
  </joint>
</robot>
